{"trial_id": "01", "hyperparameters": {"space": [{"class_name": "Float", "config": {"name": "dropout_rate", "default": 0.3, "conditions": [], "min_value": 0.2, "max_value": 0.5, "step": 0.05, "sampling": "linear"}}, {"class_name": "Choice", "config": {"name": "l2_factor", "default": 0.0001, "conditions": [], "values": [0.0001, 0.0005, 0.001], "ordered": true}}, {"class_name": "Int", "config": {"name": "n_layers_to_unfreeze", "default": 10, "conditions": [], "min_value": 5, "max_value": 30, "step": 5, "sampling": "linear"}}, {"class_name": "Float", "config": {"name": "learning_rate", "default": 0.0001, "conditions": [], "min_value": 0.0001, "max_value": 0.01, "step": null, "sampling": "log"}}], "values": {"dropout_rate": 0.4, "l2_factor": 0.0005, "n_layers_to_unfreeze": 5, "learning_rate": 0.0001392880804552672}}, "metrics": {"metrics": {}}, "score": null, "best_step": 0, "status": "FAILED", "message": "Traceback (most recent call last):\n  File \"/home/czegarra/proyectoDeep/DeepLearning_Project/env/lib/python3.12/site-packages/keras_tuner/src/engine/base_tuner.py\", line 274, in _try_run_and_update_trial\n    self._run_and_update_trial(trial, *fit_args, **fit_kwargs)\n  File \"/home/czegarra/proyectoDeep/DeepLearning_Project/env/lib/python3.12/site-packages/keras_tuner/src/engine/base_tuner.py\", line 239, in _run_and_update_trial\n    results = self.run_trial(trial, *fit_args, **fit_kwargs)\n              ^^^^^^^^^^^^^^^^^^^^^^^^^^^^^^^^^^^^^^^^^^^^^^\n  File \"/home/czegarra/proyectoDeep/DeepLearning_Project/env/lib/python3.12/site-packages/keras_tuner/src/engine/tuner.py\", line 314, in run_trial\n    obj_value = self._build_and_fit_model(trial, *args, **copied_kwargs)\n                ^^^^^^^^^^^^^^^^^^^^^^^^^^^^^^^^^^^^^^^^^^^^^^^^^^^^^^^^\n  File \"/home/czegarra/proyectoDeep/DeepLearning_Project/env/lib/python3.12/site-packages/keras_tuner/src/engine/tuner.py\", line 233, in _build_and_fit_model\n    results = self.hypermodel.fit(hp, model, *args, **kwargs)\n              ^^^^^^^^^^^^^^^^^^^^^^^^^^^^^^^^^^^^^^^^^^^^^^^\n  File \"/home/czegarra/proyectoDeep/DeepLearning_Project/env/lib/python3.12/site-packages/keras_tuner/src/engine/hypermodel.py\", line 149, in fit\n    return model.fit(*args, **kwargs)\n           ^^^^^^^^^^^^^^^^^^^^^^^^^^\n  File \"/home/czegarra/proyectoDeep/DeepLearning_Project/env/lib/python3.12/site-packages/keras/src/utils/traceback_utils.py\", line 122, in error_handler\n    raise e.with_traceback(filtered_tb) from None\n  File \"/home/czegarra/proyectoDeep/DeepLearning_Project/env/lib/python3.12/site-packages/tensorflow/python/eager/execute.py\", line 59, in quick_execute\n    except TypeError as e:\ntensorflow.python.framework.errors_impl.UnknownError: Graph execution error:\n\nDetected at node StatefulPartitionedCall defined at (most recent call last):\n  File \"/home/czegarra/proyectoDeep/DeepLearning_Project/src/training/train_xception2.py\", line 128, in <module>\n\n  File \"/home/czegarra/proyectoDeep/DeepLearning_Project/env/lib/python3.12/site-packages/keras_tuner/src/engine/base_tuner.py\", line 234, in search\n\n  File \"/home/czegarra/proyectoDeep/DeepLearning_Project/env/lib/python3.12/site-packages/keras_tuner/src/engine/base_tuner.py\", line 274, in _try_run_and_update_trial\n\n  File \"/home/czegarra/proyectoDeep/DeepLearning_Project/env/lib/python3.12/site-packages/keras_tuner/src/engine/base_tuner.py\", line 239, in _run_and_update_trial\n\n  File \"/home/czegarra/proyectoDeep/DeepLearning_Project/env/lib/python3.12/site-packages/keras_tuner/src/engine/tuner.py\", line 314, in run_trial\n\n  File \"/home/czegarra/proyectoDeep/DeepLearning_Project/env/lib/python3.12/site-packages/keras_tuner/src/engine/tuner.py\", line 233, in _build_and_fit_model\n\n  File \"/home/czegarra/proyectoDeep/DeepLearning_Project/env/lib/python3.12/site-packages/keras_tuner/src/engine/hypermodel.py\", line 149, in fit\n\n  File \"/home/czegarra/proyectoDeep/DeepLearning_Project/env/lib/python3.12/site-packages/keras/src/utils/traceback_utils.py\", line 117, in error_handler\n\n  File \"/home/czegarra/proyectoDeep/DeepLearning_Project/env/lib/python3.12/site-packages/keras/src/backend/tensorflow/trainer.py\", line 371, in fit\n\n  File \"/home/czegarra/proyectoDeep/DeepLearning_Project/env/lib/python3.12/site-packages/keras/src/backend/tensorflow/trainer.py\", line 219, in function\n\n  File \"/home/czegarra/proyectoDeep/DeepLearning_Project/env/lib/python3.12/site-packages/keras/src/backend/tensorflow/trainer.py\", line 132, in multi_step_on_iterator\n\nFailed to determine best cudnn convolution algorithm for:\n%cudnn-conv.79 = (f32[64,128,109,109]{3,2,1,0}, u8[0]{0}) custom-call(f32[64,64,109,109]{3,2,1,0} %get-tuple-element.129, f32[128,64,1,1]{3,2,1,0} %bitcast.6849), window={size=1x1}, dim_labels=bf01_oi01->bf01, custom_call_target=\"__cudnn$convForward\", metadata={op_type=\"Conv2D\" op_name=\"functional_1/block2_sepconv1_1/separable_conv2d\" source_file=\"/home/czegarra/proyectoDeep/DeepLearning_Project/env/lib/python3.12/site-packages/tensorflow/python/framework/ops.py\" source_line=1196}, backend_config={\"operation_queue_id\":\"0\",\"wait_on_operation_queues\":[],\"cudnn_conv_backend_config\":{\"conv_result_scale\":1,\"activation_mode\":\"kNone\",\"side_input_scale\":0,\"leakyrelu_alpha\":0},\"force_earliest_schedule\":false}\n\nOriginal error: RESOURCE_EXHAUSTED: Out of memory while trying to allocate 406093824 bytes.\n\nTo ignore this failure and try to use a fallback algorithm (which may have suboptimal performance), use XLA_FLAGS=--xla_gpu_strict_conv_algorithm_picker=false.  Please also file a bug for the root cause of failing autotuning.\n\t [[{{node StatefulPartitionedCall}}]] [Op:__inference_multi_step_on_iterator_20444]\n"}