{"trial_id": "03", "hyperparameters": {"space": [{"class_name": "Float", "config": {"name": "dropout_rate", "default": 0.3, "conditions": [], "min_value": 0.2, "max_value": 0.5, "step": 0.05, "sampling": "linear"}}, {"class_name": "Choice", "config": {"name": "l2_factor", "default": 0.0001, "conditions": [], "values": [0.0001, 0.0005, 0.001], "ordered": true}}, {"class_name": "Int", "config": {"name": "n_layers_to_unfreeze", "default": 10, "conditions": [], "min_value": 5, "max_value": 20, "step": 5, "sampling": "linear"}}, {"class_name": "Float", "config": {"name": "learning_rate", "default": 0.0001, "conditions": [], "min_value": 0.0001, "max_value": 0.01, "step": null, "sampling": "log"}}], "values": {"dropout_rate": 0.4, "l2_factor": 0.001, "n_layers_to_unfreeze": 5, "learning_rate": 0.00022133025724981438}}, "metrics": {"metrics": {}}, "score": null, "best_step": 0, "status": "FAILED", "message": "Traceback (most recent call last):\n  File \"/home/czegarra/env/lib/python3.12/site-packages/keras_tuner/src/engine/base_tuner.py\", line 274, in _try_run_and_update_trial\n    self._run_and_update_trial(trial, *fit_args, **fit_kwargs)\n  File \"/home/czegarra/env/lib/python3.12/site-packages/keras_tuner/src/engine/base_tuner.py\", line 239, in _run_and_update_trial\n    results = self.run_trial(trial, *fit_args, **fit_kwargs)\n              ^^^^^^^^^^^^^^^^^^^^^^^^^^^^^^^^^^^^^^^^^^^^^^\n  File \"/home/czegarra/env/lib/python3.12/site-packages/keras_tuner/src/engine/tuner.py\", line 314, in run_trial\n    obj_value = self._build_and_fit_model(trial, *args, **copied_kwargs)\n                ^^^^^^^^^^^^^^^^^^^^^^^^^^^^^^^^^^^^^^^^^^^^^^^^^^^^^^^^\n  File \"/home/czegarra/env/lib/python3.12/site-packages/keras_tuner/src/engine/tuner.py\", line 233, in _build_and_fit_model\n    results = self.hypermodel.fit(hp, model, *args, **kwargs)\n              ^^^^^^^^^^^^^^^^^^^^^^^^^^^^^^^^^^^^^^^^^^^^^^^\n  File \"/home/czegarra/env/lib/python3.12/site-packages/keras_tuner/src/engine/hypermodel.py\", line 149, in fit\n    return model.fit(*args, **kwargs)\n           ^^^^^^^^^^^^^^^^^^^^^^^^^^\n  File \"/home/czegarra/env/lib/python3.12/site-packages/keras/src/utils/traceback_utils.py\", line 122, in error_handler\n    raise e.with_traceback(filtered_tb) from None\n  File \"/home/czegarra/env/lib/python3.12/site-packages/tensorflow/python/eager/execute.py\", line 59, in quick_execute\n    except TypeError as e:\ntensorflow.python.framework.errors_impl.UnknownError: Graph execution error:\n\nDetected at node PyFunc defined at (most recent call last):\n<stack traces unavailable>\nFileNotFoundError: [Errno 2] No such file or directory: 'data/raw/Training/No_Fire/No_Fire/lake_resized_lake_frame2280.jpg'\nTraceback (most recent call last):\n\n  File \"/home/czegarra/env/lib/python3.12/site-packages/tensorflow/python/ops/script_ops.py\", line 269, in __call__\n    ret = func(*args)\n          ^^^^^^^^^^^\n\n  File \"/home/czegarra/env/lib/python3.12/site-packages/tensorflow/python/autograph/impl/api.py\", line 643, in wrapper\n    return func(*args, **kwargs)\n           ^^^^^^^^^^^^^^^^^^^^^\n\n  File \"/home/czegarra/env/lib/python3.12/site-packages/tensorflow/python/data/ops/from_generator_op.py\", line 198, in generator_py_func\n    values = next(generator_state.get_iterator(iterator_id))\n             ^^^^^^^^^^^^^^^^^^^^^^^^^^^^^^^^^^^^^^^^^^^^^^^\n\n  File \"/home/czegarra/env/lib/python3.12/site-packages/keras/src/trainers/data_adapters/py_dataset_adapter.py\", line 248, in _finite_generator\n    yield self._standardize_batch(self.py_dataset[i])\n                                  ~~~~~~~~~~~~~~~^^^\n\n  File \"/home/czegarra/env/lib/python3.12/site-packages/keras/src/legacy/preprocessing/image.py\", line 68, in __getitem__\n    return self._get_batches_of_transformed_samples(index_array)\n           ^^^^^^^^^^^^^^^^^^^^^^^^^^^^^^^^^^^^^^^^^^^^^^^^^^^^^\n\n  File \"/home/czegarra/env/lib/python3.12/site-packages/keras/src/legacy/preprocessing/image.py\", line 313, in _get_batches_of_transformed_samples\n    img = image_utils.load_img(\n          ^^^^^^^^^^^^^^^^^^^^^\n\n  File \"/home/czegarra/env/lib/python3.12/site-packages/keras/src/utils/image_utils.py\", line 235, in load_img\n    with open(path, \"rb\") as f:\n         ^^^^^^^^^^^^^^^^\n\nFileNotFoundError: [Errno 2] No such file or directory: 'data/raw/Training/No_Fire/No_Fire/lake_resized_lake_frame2280.jpg'\n\n\n\t [[{{node PyFunc}}]]\n\t [[IteratorGetNext]] [Op:__inference_multi_step_on_iterator_322862]\n"}